<?xml version="1.0"?>

<robot xmlns:xacro="http://ros.org/wiki/xacro" name="base_robot" >
  <xacro:include filename="$(find robot_description)/urdf/base_robot.urdf.xacro" />
  <xacro:include filename="$(find robot_description)/urdf/robot_arm.urdf.xacro" />
  <!-- <xacro:arm_joint prefix="arm_base_link" parent="base_link" child="arm_base"
    originxyz="0.0 0.0 0.1" originrpy="0 0 0"/> -->

  <joint name="arm_base_link_joint" type="continuous">
      <axis xyz="0 0 1"/>
      <parent link="base_link"/>
      <child link="arm_base"/>
      <origin rpy="0 0 0" xyz="0.0 0.0 0.1"/>
  </joint>
</robot>
